============================= test session starts =============================
platform win32 -- Python 3.12.3, pytest-8.2.1, pluggy-1.6.0
rootdir: E:\projetos\gem
configfile: pytest.ini
plugins: Faker-36.1.0
collected 40 items / 1 error

=================================== ERRORS ====================================
_______________ ERROR collecting tests/unit/test_image_utils.py _______________
ImportError while importing test module 'E:\projetos\gem\tests\unit\test_image_utils.py'.
Hint: make sure your test modules/packages have valid Python names.
Traceback:
C:\Program Files\Python312\Lib\importlib\__init__.py:90: in import_module
    return _bootstrap._gcd_import(name[level:], package, level)
tests\unit\test_image_utils.py:4: in <module>
    from app.utils import image_utils
app\utils\image_utils.py:7: in <module>
    from werkzeug.utils import secure_filename
E   ModuleNotFoundError: No module named 'werkzeug'
============================== warnings summary ===============================
tests\integration\test_postgres_connection.py:10
  E:\projetos\gem\tests\integration\test_postgres_connection.py:10: PytestUnknownMarkWarning: Unknown pytest.mark.integration - is this a typo?  You can register custom marks to avoid this warning - for details, see https://docs.pytest.org/en/stable/how-to/mark.html
    @pytest.mark.integration

-- Docs: https://docs.pytest.org/en/stable/how-to/capture-warnings.html
=========================== short test summary info ===========================
ERROR tests/unit/test_image_utils.py
!!!!!!!!!!!!!!!!!!! Interrupted: 1 error during collection !!!!!!!!!!!!!!!!!!!!
========================= 1 warning, 1 error in 0.65s =========================
